<?xml version="1.0"?>
<robot xmlns:xacro="http://www.ros.org/wiki/xacro">
  <xacro:property name="wheel_radius" value="0.25" />
  <xacro:property name="stl_wheel" value="package://rcg/mesh/wheel.stl"/>
  <xacro:property name="dae_wheel" value="package://rcg/mesh/wheel.dae"/>

  <xacro:macro name="wheel_velocity" params="prefix parent xyz rpy">
    <!-- Joint -->
    <joint name="${prefix}_wheel_joint" type="continuous">
      <parent link="${parent}" />
      <child link="${prefix}_wheel_link" />
      <origin xyz="${xyz}" rpy="${rpy}" />
      <axis xyz="0 0 1" />
    </joint>

    <!-- Link -->
    <link name="${prefix}_wheel_link">
      <collision>
        <geometry>
          <mesh filename="${stl_wheel}"
            scale="0.001 0.001 0.001" />
        </geometry>
      </collision>
      <visual>
        <geometry>
          <mesh filename="${dae_wheel}" />
        </geometry>
      </visual>
      <inertial>
        <origin xyz="0 0 0" />
        <mass value="1" />
        <inertia ixx="1" ixy="-4.2369783e-11" ixz="-5.9381719e-09"
          iyy="1" iyz="-1.4400107e-11"
          izz="1" />
      </inertial>
    </link>


    <!-- Transmission -->
    <transmission name="${prefix}_wheel_trans">
      <type>transmission_interface/SimpleTransmission</type>
      <joint name="${prefix}_wheel_joint">
        <hardwareInterface>hardware_interface/VelocityJointInterface</hardwareInterface>
      </joint>
      <actuator name="${prefix}_wheel_motor">
        <hardwareInterface>hardware_interface/VelocityJointInterface</hardwareInterface>
        <mechanicalReduction>1</mechanicalReduction>
      </actuator>
    </transmission>
  </xacro:macro>

  <xacro:macro name="wheel_position" params="prefix parent xyz rpy">
    <!-- Joint -->
    <joint name="${prefix}_wheel_joint" type="continuous">
      <parent link="${parent}" />
      <child link="${prefix}_wheel_link" />
      <origin xyz="${xyz}" rpy="${rpy}" />
      <axis xyz="0 0 1" />
    </joint>

    <!-- Link -->
    <link name="${prefix}_wheel_link">
      <collision>
        <geometry>
          <mesh filename="${stl_wheel}"
            scale="0.001 0.001 0.001" />
        </geometry>
      </collision>
      <visual>
        <geometry>
          <mesh filename="${dae_wheel}" />
        </geometry>
      </visual>
      <inertial>
        <origin xyz="0 0 0" />
        <mass value="1" />
        <inertia ixx="1" ixy="-4.2369783e-11" ixz="-5.9381719e-09"
          iyy="1" iyz="-1.4400107e-11"
          izz="1" />
      </inertial>
    </link>


    <!-- Transmission -->
    <transmission name="${prefix}_wheel_trans">
      <type>transmission_interface/SimpleTransmission</type>
      <joint name="${prefix}_wheel_joint">
        <hardwareInterface>hardware_interface/PositionJointInterface</hardwareInterface>
      </joint>
      <actuator name="${prefix}_wheel_motor">
        <hardwareInterface>hardware_interface/PositionJointInterface</hardwareInterface>
        <mechanicalReduction>1</mechanicalReduction>
      </actuator>
    </transmission>
  </xacro:macro>

  <xacro:macro name="wheel_torque" params="prefix parent xyz rpy">
    <!-- Joint -->
    <joint name="${prefix}_wheel_joint" type="continuous">
      <parent link="${parent}" />
      <child link="${prefix}_wheel_link" />
      <origin xyz="${xyz}" rpy="${rpy}" />
      <axis xyz="0 0 1" />
      <!-- <dynamics damping="0.1" friction="0.05"/> -->
    </joint>

    <!-- Link -->
    <link name="${prefix}_wheel_link">
      <collision>
        <geometry>
          <mesh filename="${stl_wheel}"
            scale="0.001 0.001 0.001" />
        </geometry>
      </collision>
      <visual>
        <geometry>
          <mesh filename="${dae_wheel}" />
        </geometry>
      </visual>
      <inertial>
        <origin xyz="0 0 0" />
        <mass value="1" />
        <inertia ixx="1" ixy="-4.2369783e-11" ixz="-5.9381719e-09"
          iyy="1" iyz="-1.4400107e-11"
          izz="1" />
      </inertial>
    </link>


    <!-- Transmission -->
    <transmission name="${prefix}_wheel_trans">
      <type>transmission_interface/SimpleTransmission</type>
      <joint name="${prefix}_wheel_joint">
        <hardwareInterface>hardware_interface/EffortJointInterface</hardwareInterface>
      </joint>
      <actuator name="${prefix}_wheel_motor">
        <hardwareInterface>hardware_interface/EffortJointInterface</hardwareInterface>
        <mechanicalReduction>1</mechanicalReduction>
      </actuator>
    </transmission>
  </xacro:macro>
</robot>